  <!-- Arm -->
  <link name="left_shoulder_pitch_link">
    <inertial>
      <origin xyz="0 0.035892 -0.011628" rpy="0 0 0"/>
      <mass value="0.718"/>
      <inertia ixx="0.0004291" ixy="-9.2E-06" ixz="6.4E-06" iyy="0.000453" iyz="2.26E-05" izz="0.000423"/>
    </inertial>
    <visual>
      <origin xyz="0 0 0" rpy="0 0 0"/>
      <geometry>
        <mesh filename="meshes/left_shoulder_pitch_link.STL"/>
      </geometry>
      <material name="white"/>
    </visual>
    <collision>
      <origin xyz="0 0.04 -0.01" rpy="0 1.5707963267948966 0"/>
      <geometry>
        <cylinder radius="0.03" length="0.05"/>
      </geometry>
    </collision>
  </link>
  <joint name="left_shoulder_pitch_joint" type="revolute">
    <origin xyz="0.0039563 0.10022 0.24778" rpy="0.27931 5.4949E-05 -0.00019159"/>
    <parent link="torso_link"/>
    <child link="left_shoulder_pitch_link"/>
    <axis xyz="0 1 0"/>
    <limit lower="-3.0892" upper="2.6704" effort="25" velocity="37"/>
  </joint>
  <link name="left_shoulder_roll_link">
    <inertial>
      <origin xyz="-0.000227 0.00727 -0.063243" rpy="0 0 0"/>
      <mass value="0.643"/>
      <inertia ixx="0.0006177" ixy="-1E-06" ixz="8.7E-06" iyy="0.0006912" iyz="-5.3E-06" izz="0.0003894"/>
    </inertial>
    <visual>
      <origin xyz="0 0 0" rpy="0 0 0"/>
      <geometry>
        <mesh filename="meshes/left_shoulder_roll_link.STL"/>
      </geometry>
      <material name="white"/>
    </visual>
    <collision>
      <origin xyz="-0.004 0.006 -0.053" rpy="0 0 0"/>
      <geometry>
        <cylinder radius="0.03" length="0.03"/>
      </geometry>
    </collision>
  </link>
  <joint name="left_shoulder_roll_joint" type="revolute">
    <origin xyz="0 0.038 -0.013831" rpy="-0.27925 0 0"/>
    <parent link="left_shoulder_pitch_link"/>
    <child link="left_shoulder_roll_link"/>
    <axis xyz="1 0 0"/>
    <limit lower="-1.5882" upper="2.2515" effort="25" velocity="37"/>
  </joint>
  <link name="left_shoulder_yaw_link">
    <inertial>
      <origin xyz="0.010773 -0.002949 -0.072009" rpy="0 0 0"/>
      <mass value="0.734"/>
      <inertia ixx="0.0009988" ixy="7.9E-06" ixz="0.0001412" iyy="0.0010605" iyz="-2.86E-05" izz="0.0004354"/>
    </inertial>
    <visual>
      <origin xyz="0 0 0" rpy="0 0 0"/>
      <geometry>
        <mesh filename="meshes/left_shoulder_yaw_link.STL"/>
      </geometry>
      <material name="white"/>
    </visual>
    <collision>
      <origin xyz="0 0 0" rpy="0 0 0"/>
      <geometry>
        <mesh filename="meshes/left_shoulder_yaw_link.STL"/>
      </geometry>
    </collision>
  </link>
  <joint name="left_shoulder_yaw_joint" type="revolute">
    <origin xyz="0 0.00624 -0.1032" rpy="0 0 0"/>
    <parent link="left_shoulder_roll_link"/>
    <child link="left_shoulder_yaw_link"/>
    <axis xyz="0 0 1"/>
    <limit lower="-2.618" upper="2.618" effort="25" velocity="37"/>
  </joint>
  <link name="left_elbow_link">
    <inertial>
      <origin xyz="0.064956 0.004454 -0.010062" rpy="0 0 0"/>
      <mass value="0.6"/>
      <inertia ixx="0.0002891" ixy="6.53E-05" ixz="1.72E-05" iyy="0.0004152" iyz="-5.6E-06" izz="0.0004197"/>
    </inertial>
    <visual>
      <origin xyz="0 0 0" rpy="0 0 0"/>
      <geometry>
        <mesh filename="meshes/left_elbow_link.STL"/>
      </geometry>
      <material name="white"/>
    </visual>
    <collision>
      <origin xyz="0 0 0" rpy="0 0 0"/>
      <geometry>
        <mesh filename="meshes/left_elbow_link.STL"/>
      </geometry>
    </collision>
  </link>
  <joint name="left_elbow_joint" type="revolute">
    <origin xyz="0.015783 0 -0.080518" rpy="0 0 0"/>
    <parent link="left_shoulder_yaw_link"/>
    <child link="left_elbow_link"/>
    <axis xyz="0 1 0"/>
    <limit lower="-1.0472" upper="2.0944" effort="25" velocity="37"/>
  </joint>
  <joint name="left_wrist_roll_joint" type="revolute">
    <origin xyz="0.100 0.00188791 -0.010" rpy="0 0 0"/>
    <axis xyz="1 0 0"/>
    <parent link="left_elbow_link"/>
    <child link="left_wrist_roll_link"/>
    <limit effort="25" velocity="37" lower="-1.972222054" upper="1.972222054"/>
  </joint>
  <link name="left_wrist_roll_link">
    <inertial>
      <origin xyz="0.01713944778 0.00053759094 0.00000048864" rpy="0 0 0"/>
      <mass value="0.08544498"/>
      <inertia ixx="0.00004821544023" ixy="-0.00000424511021" ixz="0.00000000510599" iyy="0.00003722899093" iyz="-0.00000000123525" izz="0.00005482106541"/>
    </inertial>
    <visual>
      <origin xyz="0 0 0" rpy="0 0 0"/>
      <geometry>
        <mesh filename="meshes/left_wrist_roll_link.STL"/>
      </geometry>
      <material name="white"/>
    </visual>
    <collision>
      <origin xyz="0 0 0" rpy="0 0 0"/>
      <geometry>
        <mesh filename="meshes/left_wrist_roll_link.STL"/>
      </geometry>
    </collision>
  </link>
  <joint name="left_wrist_pitch_joint" type="revolute">
    <origin xyz="0.038 0 0" rpy="0 0 0"/>
    <axis xyz="0 1 0"/>
    <parent link="left_wrist_roll_link"/>
    <child link="left_wrist_pitch_link"/>
    <limit effort="5" velocity="22" lower="-1.614429558" upper="1.614429558"/>
  </joint>
  <link name="left_wrist_pitch_link">
    <inertial>
      <origin xyz="0.02299989837 -0.00111685314 -0.00111658096" rpy="0 0 0"/>
      <mass value="0.48404956"/>
      <inertia ixx="0.00016579646273" ixy="-0.00001231206746" ixz="0.00001231699194" iyy="0.00042954057410" iyz="0.00000081417712" izz="0.00042953697654"/>
    </inertial>
    <visual>
      <origin xyz="0 0 0" rpy="0 0 0"/>
      <geometry>
        <mesh filename="meshes/left_wrist_pitch_link.STL"/>
      </geometry>
      <material name="white"/>
    </visual>
    <collision>
      <origin xyz="0 0 0" rpy="0 0 0"/>
      <geometry>
        <mesh filename="meshes/left_wrist_pitch_link.STL"/>
      </geometry>
    </collision>
  </link>
  <joint name="left_wrist_yaw_joint" type="revolute">
    <origin xyz="0.046 0 0" rpy="0 0 0"/>
    <axis xyz="0 0 1"/>
    <parent link="left_wrist_pitch_link"/>
    <child link="left_wrist_yaw_link"/>
    <limit effort="5" velocity="22" lower="-1.614429558" upper="1.614429558"/>
  </joint>
  <link name="left_wrist_yaw_link">
    <inertial>
      <origin xyz="0.02200381568 0.00049485096 0.00053861123" rpy="0 0 0"/>
      <mass value="0.08457647"/>
      <inertia ixx="0.00004929128828" ixy="-0.00000045735494" ixz="0.00000445867591" iyy="0.00005973338134" iyz="0.00000043217198" izz="0.00003928083826"/>
    </inertial>
    <visual>
      <origin xyz="0 0 0" rpy="0 0 0"/>
      <geometry>
        <mesh filename="meshes/left_wrist_yaw_link.STL"/>
      </geometry>
      <material name="white"/>
    </visual>
    <collision>
      <origin xyz="0 0 0" rpy="0 0 0"/>
      <geometry>
        <mesh filename="meshes/left_wrist_yaw_link.STL"/>
      </geometry>
    </collision>
  </link>  
  <link name="right_shoulder_pitch_link">
      <inertial>
        <origin xyz="0 -0.035892 -0.011628" rpy="0 0 0"/>
        <mass value="0.718"/>
        <inertia ixx="0.0004291" ixy="9.2E-06" ixz="6.4E-06" iyy="0.000453" iyz="-2.26E-05" izz="0.000423"/>
      </inertial>
      <visual>
        <origin xyz="0 0 0" rpy="0 0 0"/>
        <geometry>
          <mesh filename="meshes/right_shoulder_pitch_link.STL"/>
        </geometry>
        <material name="white"/>
      </visual>
      <collision>
        <origin xyz="0 -0.04 -0.01" rpy="0 1.5707963267948966 0"/>
        <geometry>
          <cylinder radius="0.03" length="0.05"/>
        </geometry>
      </collision>
    </link>
    <joint name="right_shoulder_pitch_joint" type="revolute">
      <origin xyz="0.0039563 -0.10021 0.24778" rpy="-0.27931 5.4949E-05 0.00019159"/>
      <parent link="torso_link"/>
      <child link="right_shoulder_pitch_link"/>
      <axis xyz="0 1 0"/>
      <limit lower="-3.0892" upper="2.6704" effort="25" velocity="37"/>
    </joint>
    <link name="right_shoulder_roll_link">
      <inertial>
        <origin xyz="-0.000227 -0.00727 -0.063243" rpy="0 0 0"/>
        <mass value="0.643"/>
        <inertia ixx="0.0006177" ixy="1E-06" ixz="8.7E-06" iyy="0.0006912" iyz="5.3E-06" izz="0.0003894"/>
      </inertial>
      <visual>
        <origin xyz="0 0 0" rpy="0 0 0"/>
        <geometry>
          <mesh filename="meshes/right_shoulder_roll_link.STL"/>
        </geometry>
        <material name="white"/>
      </visual>
      <collision>
        <origin xyz="-0.004 -0.006 -0.053" rpy="0 0 0"/>
        <geometry>
          <cylinder radius="0.03" length="0.03"/>
        </geometry>
      </collision>
    </link>
    <joint name="right_shoulder_roll_joint" type="revolute">
      <origin xyz="0 -0.038 -0.013831" rpy="0.27925 0 0"/>
      <parent link="right_shoulder_pitch_link"/>
      <child link="right_shoulder_roll_link"/>
      <axis xyz="1 0 0"/>
      <limit lower="-2.2515" upper="1.5882" effort="25" velocity="37"/>
    </joint>
    <link name="right_shoulder_yaw_link">
      <inertial>
        <origin xyz="0.010773 0.002949 -0.072009" rpy="0 0 0"/>
        <mass value="0.734"/>
        <inertia ixx="0.0009988" ixy="-7.9E-06" ixz="0.0001412" iyy="0.0010605" iyz="2.86E-05" izz="0.0004354"/>
      </inertial>
      <visual>
        <origin xyz="0 0 0" rpy="0 0 0"/>
        <geometry>
          <mesh filename="meshes/right_shoulder_yaw_link.STL"/>
        </geometry>
        <material name="white"/>
      </visual>
      <collision>
        <origin xyz="0 0 0" rpy="0 0 0"/>
        <geometry>
          <mesh filename="meshes/right_shoulder_yaw_link.STL"/>
        </geometry>
      </collision>
    </link>
    <joint name="right_shoulder_yaw_joint" type="revolute">
      <origin xyz="0 -0.00624 -0.1032" rpy="0 0 0"/>
      <parent link="right_shoulder_roll_link"/>
      <child link="right_shoulder_yaw_link"/>
      <axis xyz="0 0 1"/>
      <limit lower="-2.618" upper="2.618" effort="25" velocity="37"/>
    </joint>
    <link name="right_elbow_link">
      <inertial>
        <origin xyz="0.064956 -0.004454 -0.010062" rpy="0 0 0"/>
        <mass value="0.6"/>
        <inertia ixx="0.0002891" ixy="-6.53E-05" ixz="1.72E-05" iyy="0.0004152" iyz="5.6E-06" izz="0.0004197"/>
      </inertial>
      <visual>
        <origin xyz="0 0 0" rpy="0 0 0"/>
        <geometry>
          <mesh filename="meshes/right_elbow_link.STL"/>
        </geometry>
        <material name="white"/>
      </visual>
      <collision>
        <origin xyz="0 0 0" rpy="0 0 0"/>
        <geometry>
          <mesh filename="meshes/right_elbow_link.STL"/>
        </geometry>
      </collision>
    </link>
    <joint name="right_elbow_joint" type="revolute">
      <origin xyz="0.015783 0 -0.080518" rpy="0 0 0"/>
      <parent link="right_shoulder_yaw_link"/>
      <child link="right_elbow_link"/>
      <axis xyz="0 1 0"/>
      <limit lower="-1.0472" upper="2.0944" effort="25" velocity="37"/>
    </joint>
    <joint name="right_wrist_roll_joint" type="revolute">
      <origin xyz="0.100 -0.00188791 -0.010" rpy="0 0 0"/>
      <axis xyz="1 0 0"/>
      <parent link="right_elbow_link"/>
      <child link="right_wrist_roll_link"/>
      <limit effort="25" velocity="37" lower="-1.972222054" upper="1.972222054"/>
    </joint>
    <link name="right_wrist_roll_link">
      <inertial>
        <origin xyz="0.01713944778 -0.00053759094 0.00000048864" rpy="0 0 0"/>
        <mass value="0.08544498"/>
        <inertia ixx="0.00004821544023" ixy="0.00000424511021" ixz="0.00000000510599" iyy="0.00003722899093" iyz="0.00000000123525" izz="0.00005482106541"/>
      </inertial>
      <visual>
        <origin xyz="0 0 0" rpy="0 0 0"/>
        <geometry>
          <mesh filename="meshes/right_wrist_roll_link.STL"/>
        </geometry>
        <material name="white"/>
      </visual>
      <collision>
        <origin xyz="0 0 0" rpy="0 0 0"/>
        <geometry>
          <mesh filename="meshes/right_wrist_roll_link.STL"/>
        </geometry>
      </collision>
    </link>
    <joint name="right_wrist_pitch_joint" type="revolute">
      <origin xyz="0.038 0 0" rpy="0 0 0"/>
      <axis xyz="0 1 0"/>
      <parent link="right_wrist_roll_link"/>
      <child link="right_wrist_pitch_link"/>
      <limit effort="5" velocity="22" lower="-1.614429558" upper="1.614429558"/>
    </joint>
    <link name="right_wrist_pitch_link">
      <inertial>
        <origin xyz="0.02299989837 0.00111685314 -0.00111658096" rpy="0 0 0"/>
        <mass value="0.48404956"/>
        <inertia ixx="0.00016579646273" ixy="0.00001231206746" ixz="0.00001231699194" iyy="0.00042954057410" iyz="-0.00000081417712" izz="0.00042953697654"/>
      </inertial>
      <visual>
        <origin xyz="0 0 0" rpy="0 0 0"/>
        <geometry>
          <mesh filename="meshes/right_wrist_pitch_link.STL"/>
        </geometry>
        <material name="white"/>
      </visual>
      <collision>
        <origin xyz="0 0 0" rpy="0 0 0"/>
        <geometry>
          <mesh filename="meshes/right_wrist_pitch_link.STL"/>
        </geometry>
      </collision>
    </link>
    <joint name="right_wrist_yaw_joint" type="revolute">
      <origin xyz="0.046 0 0" rpy="0 0 0"/>
      <axis xyz="0 0 1"/>
      <parent link="right_wrist_pitch_link"/>
      <child link="right_wrist_yaw_link"/>
      <limit effort="5" velocity="22" lower="-1.614429558" upper="1.614429558"/>
    </joint>
    <link name="right_wrist_yaw_link">
      <inertial>
        <origin xyz="0.02200381568 -0.00049485096 0.00053861123" rpy="0 0 0"/>
        <mass value="0.08457647"/>
        <inertia ixx="0.00004929128828" ixy="0.00000045735494" ixz="0.00000445867591" iyy="0.00005973338134" iyz="-0.00000043217198" izz="0.00003928083826"/>
      </inertial>
      <visual>
        <origin xyz="0 0 0" rpy="0 0 0"/>
        <geometry>
          <mesh filename="meshes/right_wrist_yaw_link.STL"/>
        </geometry>
        <material name="white"/>
      </visual>
      <collision>
        <origin xyz="0 0 0" rpy="0 0 0"/>
        <geometry>
          <mesh filename="meshes/right_wrist_yaw_link.STL"/>
        </geometry>
      </collision>
    </link>
    <joint name="right_hand_palm_joint" type="fixed">
      <origin xyz="0.0415 -0.003 0" rpy="0 0 0"/>
      <parent link="right_wrist_yaw_link"/>
      <child link="right_hand_palm_link"/>
    </joint>