  <!-- Torso -->
  <link name="waist_yaw_link">
    <inertial>
      <origin xyz="0.003494 0.000233 0.018034" rpy="0 0 0"/>
      <mass value="0.214"/>
      <inertia ixx="0.00010673" ixy="2.703E-06" ixz="-7.631E-06" iyy="0.00010422" iyz="-2.01E-07" izz="0.0001625"/>
    </inertial>
    <visual>
      <origin xyz="0 0 0" rpy="0 0 0"/>
      <geometry>
        <mesh filename="meshes/waist_yaw_link_rev_1_0.STL"/>
      </geometry>
      <material name="white"/>
    </visual>
  </link>
  <joint name="waist_yaw_joint" type="revolute">
    <origin xyz="0 0 0" rpy="0 0 0"/>
    <parent link="pelvis"/>
    <child link="waist_yaw_link"/>
    <axis xyz="0 0 1"/>
    <limit lower="-2.618" upper="2.618" effort="88" velocity="32"/>
  </joint>
  <link name="waist_roll_link">
    <inertial>
      <origin xyz="0 2.3E-05 0" rpy="0 0 0"/>
      <mass value="0.086"/>
      <inertia ixx="7.079E-06" ixy="0" ixz="0" iyy="6.339E-06" iyz="0" izz="8.245E-06"/>
    </inertial>
    <visual>
      <origin xyz="0 0 0" rpy="0 0 0"/>
      <geometry>
        <mesh filename="meshes/waist_roll_link_rev_1_0.STL"/>
      </geometry>
      <material name="white"/>
    </visual>
  </link>
  <joint name="waist_roll_joint" type="revolute">
    <origin xyz="-0.0039635 0 0.044" rpy="0 0 0"/>
    <parent link="waist_yaw_link"/>
    <child link="waist_roll_link"/>
    <axis xyz="1 0 0"/>
    <limit lower="-0.52" upper="0.52" effort="35" velocity="30"/>
  </joint>
  <link name="torso_link">
    <inertial>
      <origin xyz="0.000931 0.000346 0.15082" rpy="0 0 0"/>
      <mass value="6.78"/>
      <inertia ixx="0.05905" ixy="3.3302E-05" ixz="-0.0017715" iyy="0.047014" iyz="-2.2399E-05" izz="0.025652"/>
    </inertial>
    <visual>
      <origin xyz="0 0 0" rpy="0 0 0"/>
      <geometry>
        <mesh filename="meshes/torso_link_rev_1_0.STL"/>
      </geometry>
      <material name="white"/>
    </visual>
    <collision>
      <origin xyz="0 0 0" rpy="0 0 0"/>
      <geometry>
        <mesh filename="meshes/torso_link_rev_1_0.STL"/>
      </geometry>
    </collision>
  </link>
  <joint name="waist_pitch_joint" type="revolute">
    <origin xyz="0 0 0" rpy="0 0 0"/>
    <parent link="waist_roll_link"/>
    <child link="torso_link"/>
    <axis xyz="0 1 0"/>
    <limit lower="-0.52" upper="0.52" effort="35" velocity="30"/>
  </joint>